Workbook

Sheet Dashboard
A1: To pay back | F1: Monthly payment | L1: Trả chị Diễm
A2: Owner | C2: Amount (N) | F2: Name | H2: Amount (N) | I2: Charge date | L2: Đợt | M2: Số tiền | N2: Ngày
F3: Shinhan | H3: 1700 | I3: 1 | L3: 1 | M3: 5000 | N3: 46053
F4: YouTube Premium | H4: 52 | I4: 12 | L4: 2 | M4: 2000 | N4: 46081
F5: Gonsa | H5: 5000 | I5: 15 | L5: 3 | M5: 1000 | N5: 46112
F6: Vinaphone 4G | H6: 70 | I6: 26 | L6: 4 | M6: 500 | N6: 46116
L7: 5 | M7: 1000 | N7: 46142
A8: To earn back | L8: 6 | M8: 500 | N8: 46147
A9: Debtors | C9: Amount (N) | D9: Reason | L9: 7 | M9: 1000 | N9: 46233
A10: Khôi | C10: 2750 | D10: Lost | L10: 8
A11: Nguyệt | C11: 3000 | D11: Lost | L11: 9
A12: Bảo | C12: 400 | L12: 10
L13: 11
L14: 12
L15: 13
L16: 14
L17: 15
L18: 16
L19: 17
L20: Tổng | M20: =SUM(M3:M19) -> 11000 | N20: / 50000

Sheet T102026
A1: DATE | B1: SPENT FOR | C1: AMOUNT | D1: TYPE | F1: DATE | G1: EARN BY | H1: AMOUNT
A2: 46294 | B2: Trả Thiên | C2: 1000 | D2: Trả tiền mượn sinh hoạt | F2: 46294 | G2: Lương T9 + Dư T9 | H2: =24357+'T92026'!G18 -> 24485
B3: Trả A Khoa | C3: 2000 | D3: Trả tiền mượn sinh hoạt | H3: 5500
B4: Help Bảo | C4: 300 | D4: Support
B5: Trả tín dụng | C5: 1000 | D5: Trả tín dụng
B6: Trả Phúc | C6: 550 | D6: Trả tiền mượn sinh hoạt
B7: Đổ xăng | C7: 70 | D7: Thiết yếu
B8: Lê Trang | C8: 57 | D8: Living expense
B9: Cho Má | C9: 3000 | D9: Tiền ăn ba má
B10: Tạp hóa | C10: 89 | D10: Living expense
B11: Claude Code | C11: 600 | D11: Công việc
B12: Trả cô Ánh | C12: 800 | D12: Trả tiền mượn sinh hoạt
A13: 46295 | B13: HBO Max | C13: 135 | D13: Credit | F13: Total earn | G13: =SUM(H2:H12) -> 29985
B14: Ăn trưa | C14: 60 | D14: Living expense | F14: Total spent | G14: =SUMPRODUCT(((D2:D233<>"Credit")*(D2:D233<>"Quỹ Shinhan"))*C2:C233) + G15 -> 12623
B15: Sửa xe | C15: 75 | D15: Thiết yếu | F15: Untrack spent | G15: =39 -> 39
B16: Bún riêu | C16: 25 | D16: Living expense | F16: Saving | G16: 0
A17: 46296 | B17: Shinhan | C17: 1700 | D17: Shinhan
B18: Nước ngọt | C18: 16 | D18: Living expense | F18: Remaining | G18: =G13-G14-J26 -> 5318
B19: Cơm gà Lê Trang | C19: 45 | D19: Living expense | F19: Remaining (- liabilities) | G19: =G13-G14 -> 17362
B20: Nước bình | C20: 160 | D20: Thiết yếu
B21: Grab | C21: 20 | D21: Living expense | F21: Category | G21: Estimated | H21: Actual
A22: 46297 | B22: Grab | C22: 14 | D22: Living expense | F22: Living expense | G22: 8000 | H22: =SUMIF(D2:D156, "=Living expense",C2:C174)+G15 -> 412
B23: Ăn trưa | C23: 38 | D23: Living expense
B24: Tiền điện Trà Vinh | C24: 10 | D24: Tiền nhà | F24: Planned/actual spend per category of this month
B25: Tiền điện Cần Thơ | C25: 646 | D25: Tiền nhà | F25: Category | G25: Estimated | H25: Actual | I25: Finalize | J25: Reserve
B26: Trả Ly | C26: 300 | D26: Special | F26: Sum | G26: =SUM(G27:G111) -> 23530 | H26: =SUM(H27:H111) -> 10706 | J26: =SUM(J27:J111) -> 12044
B27: Hủ tiếu | C27: 30 | D27: Living expense | F27: Tiền nhà | G27: 7200 | H27: =IFERROR(__xludf.DUMMYFUNCTION("SUMIF($D$2:$D$532, TO_TEXT(F27) ,$C$2:$C$532)"),656.0) -> 656 | I27: FALSE | J27: =IF(I27=TRUE,0,MAX(G27-H27,0)) -> 6544
B28: Nước ngọt | C28: 24 | D28: Living expense | F28: Gonsa | G28: 5000 | H28: =IFERROR(__xludf.DUMMYFUNCTION("SUMIF($D$2:$D$532, TO_TEXT(F28) ,$C$2:$C$532)"),0.0) -> 0 | I28: FALSE | J28: =IF(I28=TRUE,0,MAX(G28-H28,0)) -> 5000
B29: Toàn HBO Max | C29: -45 | D29: Living expense | F29: Trả tiền mượn sinh hoạt | G29: =2000+1000+550+800 -> 4350 | H29: =IFERROR(__xludf.DUMMYFUNCTION("SUMIF($D$2:$D$532, TO_TEXT(F29) ,$C$2:$C$532)"),4350.0) -> 4350 | I29: TRUE | J29: =IF(I29=TRUE,0,MAX(G29-H29,0)) -> 0
D30: Living expense | F30: Trả tín dụng | G30: 1000 | H30: =IFERROR(__xludf.DUMMYFUNCTION("SUMIF($D$2:$D$532, TO_TEXT(F30) ,$C$2:$C$532)"),1000.0) -> 1000 | I30: TRUE | J30: =IF(I30=TRUE,0,MAX(G30-H30,0)) -> 0
D31: Living expense | F31: Shinhan | G31: 1700 | H31: =IFERROR(__xludf.DUMMYFUNCTION("SUMIF($D$2:$D$532, TO_TEXT(F31) ,$C$2:$C$532)"),1700.0) -> 1700 | I31: TRUE | J31: =IF(I31=TRUE,0,MAX(G31-H31,0)) -> 0
D32: Living expense | F32: Tiền ăn ba má | G32: 3000 | H32: =IFERROR(__xludf.DUMMYFUNCTION("SUMIF($D$2:$D$532, TO_TEXT(F32) ,$C$2:$C$532)"),3000.0) -> 3000 | I32: TRUE | J32: =IF(I32=TRUE,0,MAX(G32-H32,0)) -> 0
D33: Living expense | F33: Sức khỏe | G33: 500 | H33: =IFERROR(__xludf.DUMMYFUNCTION("SUMIF($D$2:$D$532, TO_TEXT(F33) ,$C$2:$C$532)"),0.0) -> 0 | I33: FALSE | J33: =IF(I33=TRUE,0,MAX(G33-H33,0)) -> 500
D34: Living expense | F34: Dịch vụ | G34: =600+180 -> 780 | H34: =IFERROR(__xludf.DUMMYFUNCTION("SUMIF($D$2:$D$532, TO_TEXT(F34) ,$C$2:$C$532)"),0.0) -> 0 | I34: TRUE | J34: =IF(I34=TRUE,0,MAX(G34-H34,0)) -> 0
D35: Living expense
D36: Living expense
D37: Living expense
D38: Living expense
D39: Living expense
D40: Living expense
...

Sheet T92026
A1: DATE | B1: SPENT FOR | C1: AMOUNT | D1: TYPE | F1: DATE | G1: EARN BY | H1: AMOUNT
A2: 46262 | B2: Ăn trưa | C2: 38 | D2: Living expense | F2: 46261 | G2: Lương T8 + Dư T8 | H2: =24357+'T82026'!G18 -> 27917
B3: Nước ngọt | C3: 16 | D3: Living expense | G3: A Bảo support | H3: 1000
B4: Jolibee | C4: 93 | D4: Living expense | F4: 46280 | G4: Thiên Help | H4: 1000
B5: Cơm cho Má | C5: 63 | D5: Living expense | G5: Má cho mượn | H5: 2000
B6: Trả Khang | C6: 2000 | D6: Trả Khang | G6: A Khoa cho mượn | H6: 2000
A7: 46263 | B7: Khám bệnh cho Má | C7: =100+218 -> 318 | D7: Sức khỏe | F7: 46281 | G7: A Bảo support | H7: 500
B8: Highland | C8: 60 | D8: Living expense | F8: 46288 | G8: Má cho | H8: 50
B9: Ăn sáng | C9: 28 | D9: Living expense | F9: 46288 | G9: Má mượn cho | H9: 500
B10: Ăn chiều | C10: 70 | D10: Living expense | F10: 46289 | G10: Bảo cho | H10: 200
B11: Ăn tối | C11: 66 | D11: Living expense | F11: 46291 | G11: Phúc help | H11: 500
A12: 46264 | B12: Khám bệnh cho Ba | C12: =130+61+62 -> 253 | D12: Sức khỏe
B13: Bánh mì | C13: 19 | D13: Living expense | F13: Total earn | G13: =SUM(H2:H12) -> 35667
B14: Ăn trưa với Má | C14: 64 | D14: Living expense | F14: Total spent | G14: =SUMPRODUCT(((D2:D233<>"Credit")*(D2:D233<>"Quỹ Shinhan"))*C2:C233) + G15 -> 35539
B15: Mua sắm siêu thị | C15: 305 | D15: Living expense | F15: Untrack spent | G15: =-62+103+45-156+1+108+205+81+101+81+32+6 -> 545
B16: Tiền ăn ba má | C16: 4000 | D16: Tiền ăn ba má | F16: Saving | G16: 0
B17: Ăn tối | C17: 69 | D17: Living expense
B18: HBO Max | C18: =99+36 -> 135 | D18: Credit | F18: Remaining | G18: =G13-G14-J26 -> 128
B19: Trả tín dụng | C19: 1500 | D19: Trả tín dụng | F19: Remaining (- liabilities) | G19: =G13-G14 -> 128
A20: 46265 | B20: Taxi về quê | C20: 1002 | D20: Taxi về quê
B21: Nạp 4G cho Má | C21: 20 | D21: Parent | F21: Category | G21: Estimated | H21: Actual
B22: Bún nem nướng | C22: 89 | D22: Living expense | F22: Living expense | G22: 8000 | H22: =SUMIF(D2:D156, "=Living expense",C2:C174)+G15 -> 8122
B23: Game | C23: 45 | D23: Living expense
B24: Vé phim | C24: 127 | D24: Living expense | F24: Planned/actual spend per category of this month
A25: 46266 | B25: Cơm | C25: 25 | D25: Living expense | F25: Category | G25: Estimated | H25: Actual | I25: Finalize | J25: Reserve
B26: Trung Nguyên Vincom | C26: 53 | D26: Living expense | F26: Sum | G26: =SUM(G27:G111) -> 25000 | H26: =SUM(H27:H111) -> 26541 | J26: =SUM(J27:J111) -> 0
B27: Nước rạp phim | C27: 89 | D27: Living expense | F27: Tiền nhà | G27: 7200 | H27: =IFERROR(__xludf.DUMMYFUNCTION("SUMIF($D$2:$D$532, TO_TEXT(F27) ,$C$2:$C$532)"),7268.0) -> 7268 | I27: TRUE | J27: =IF(I27=TRUE,0,MAX(G27-H27,0)) -> 0
B28: Bún nem nướng | C28: 89 | D28: Living expense | F28: Gonsa | G28: 5000 | H28: =IFERROR(__xludf.DUMMYFUNCTION("SUMIF($D$2:$D$532, TO_TEXT(F28) ,$C$2:$C$532)"),5000.0) -> 5000 | I28: TRUE | J28: =IF(I28=TRUE,0,MAX(G28-H28,0)) -> 0
B29: Shinhan | C29: 1700 | D29: Shinhan | F29: Help Ly | G29: 2000 | H29: =IFERROR(__xludf.DUMMYFUNCTION("SUMIF($D$2:$D$532, TO_TEXT(F29) ,$C$2:$C$532)"),2000.0) -> 2000 | I29: TRUE | J29: =IF(I29=TRUE,0,MAX(G29-H29,0)) -> 0
B30: Bánh mì | C30: 20 | D30: Living expense | F30: Trả tín dụng | G30: 1500 | H30: =IFERROR(__xludf.DUMMYFUNCTION("SUMIF($D$2:$D$532, TO_TEXT(F30) ,$C$2:$C$532)"),1500.0) -> 1500 | I30: TRUE | J30: =IF(I30=TRUE,0,MAX(G30-H30,0)) -> 0
A31: 46267 | B31: Ăn sáng | C31: 35 | D31: Living expense | F31: Shinhan | G31: 1700 | H31: =IFERROR(__xludf.DUMMYFUNCTION("SUMIF($D$2:$D$532, TO_TEXT(F31) ,$C$2:$C$532)"),1700.0) -> 1700 | I31: TRUE | J31: =IF(I31=TRUE,0,MAX(G31-H31,0)) -> 0
B32: Cafe | C32: 35 | D32: Living expense | F32: Tiền ăn ba má | G32: 3000 | H32: =IFERROR(__xludf.DUMMYFUNCTION("SUMIF($D$2:$D$532, TO_TEXT(F32) ,$C$2:$C$532)"),3000.0) -> 3000 | I32: TRUE | J32: =IF(I32=TRUE,0,MAX(G32-H32,0)) -> 0
B33: Genshin | C33: 129 | D33: Credit | F33: Sức khỏe | G33: 600 | H33: =IFERROR(__xludf.DUMMYFUNCTION("SUMIF($D$2:$D$532, TO_TEXT(F33) ,$C$2:$C$532)"),2216.0) -> 2216 | I33: TRUE | J33: =IF(I33=TRUE,0,MAX(G33-H33,0)) -> 0
B34: Net | C34: 50 | D34: Living expense | F34: Trả Khang | G34: 2000 | H34: =IFERROR(__xludf.DUMMYFUNCTION("SUMIF($D$2:$D$532, TO_TEXT(F34) ,$C$2:$C$532)"),2000.0) -> 2000 | I34: TRUE | J34: =IF(I34=TRUE,0,MAX(G34-H34,0)) -> 0
B35: Đồ chiên | C35: 50 | D35: Living expense | F35: Taxi về quê | G35: 2000 | H35: =IFERROR(__xludf.DUMMYFUNCTION("SUMIF($D$2:$D$532, TO_TEXT(F35) ,$C$2:$C$532)"),1857.0) -> 1857 | I35: TRUE | J35: =IF(I35=TRUE,0,MAX(G35-H35,0)) -> 0
B36: Tiền điện Trà Vinh | C36: 10 | D36: Tiền nhà
B37: Taxi | C37: 855 | D37: Taxi về quê
A38: 46268 | B38: Trà | C38: 20 | D38: Living expense
B39: Tiền điện Cần Thơ | C39: 769 | D39: Tiền nhà
B40: Tiền Wifi | C40: 240 | D40: Tiền nhà
...

Sheet T82026
A1: DATE | B1: SPENT FOR | C1: AMOUNT | D1: TYPE | F1: DATE | G1: EARN BY | H1: AMOUNT
A2: 46233 | B2: Ăn trưa | C2: 30 | D2: Living expense | F2: 46233 | G2: Lương T7 + Dư T7 | H2: =24357+'T72026'!G18 -> 24468
B3: Sữa | C3: 14 | D3: Living expense | F3: 46239 | G3: Lương Ba | H3: 5500
B4: Trả Khang | C4: 2000 | D4: Trả Khang | F4: 46240 | G4: Má gởi | H4: 200
B5: Trả tín dụng | C5: 1000 | D5: Trả tín dụng | G5: Bảo gởi | H5: 100
B6: Cơm gà | C6: =218-56-41-33-45 -> 43 | D6: Living expense | F6: 46254 | G6: Khang help | H6: 2000
B7: Sữa | C7: 26 | D7: Living expense | F7: 46255 | G7: Tiền thưởng của Ba | H7: 650
B8: Bún riêu cho Má | C8: 30 | D8: Parent | F8: 46258 | G8: Lương Ba | H8: 5580
B9: Gởi Má | C9: 4500 | D9: Tiền ăn ba má
B10: Trả chị Diễm | C10: 1000 | D10: Trả chị Diễm
A11: 46234 | B11: Ăn trưa | C11: 40 | D11: Living expense
B12: Sữa | C12: 14 | D12: Living expense
B13: Ăn chiều | C13: 57 | D13: Living expense | F13: Total earn | G13: =SUM(H2:H12) -> 38498
B14: Bột chiên | C14: 54 | D14: Living expense | F14: Total spent | G14: =SUMPRODUCT(((D2:D231<>"Credit")*(D2:D231<>"Quỹ Shinhan"))*C2:C231) + G15 -> 34938
A15: 46235 | B15: Khám bệnh | C15: =100+100+68+70 -> 338 | D15: Sức khỏe | F15: Untrack spent | G15: =-2+62+3+77+224+412+76+47 -> 899
B16: Highland | C16: 59 | D16: Living expense | F16: Saving | G16: 0
B17: Nước ngọt | C17: 24 | D17: Living expense
B18: Shinhan | C18: 1700 | D18: Shinhan | F18: Remaining | G18: =G13-G14-J26 -> 3560
B19: Help Ly | C19: 1500 | D19: Help Ly | F19: Remaining (- liabilities) | G19: =G13-G14 -> 3560
A20: 46236 | B20: Ăn trưa | C20: 60 | D20: Living expense
B21: Tiền điện | C21: 786 | D21: Tiền nhà | F21: Category | G21: Estimated | H21: Actual
B22: WiFi | C22: 189 | D22: Tiền nhà | F22: Living expense | G22: 8000 | H22: =SUMIF(D2:D154, "=Living expense",C2:C172)+G15 -> 7814
B23: Tiền kết | C23: 20 | D23: Living expense
B24: Bò kho | C24: 80 | D24: Living expense | F24: Planned/actual spend per category of this month
B25: GO | C25: 603 | D25: Credit | F25: Category | G25: Estimated | H25: Actual | I25: Finalize | J25: Reserve
B26: Sách | C26: 220 | D26: Living expense | F26: Sum | G26: =SUM(G27:G109) -> 26700 | H26: =SUM(H27:H109) -> 25612 | J26: =SUM(J27:J109) -> 0
B27: Sữa | C27: 26 | D27: Living expense | F27: Tiền nhà | G27: 7200 | H27: =IFERROR(__xludf.DUMMYFUNCTION("SUMIF($D$2:$D$530, TO_TEXT(F27) ,$C$2:$C$530)"),7074.0) -> 7074 | I27: TRUE | J27: =IF(I27=TRUE,0,MAX(G27-H27,0)) -> 0
A28: 46237 | B28: Trà | C28: 18 | D28: Living expense | F28: Gonsa | G28: 5000 | H28: =IFERROR(__xludf.DUMMYFUNCTION("SUMIF($D$2:$D$530, TO_TEXT(F28) ,$C$2:$C$530)"),5000.0) -> 5000 | I28: TRUE | J28: =IF(I28=TRUE,0,MAX(G28-H28,0)) -> 0
B29: Trả tiền ăn cty | C29: 290 | D29: Living expense | F29: Help Ly | G29: 3000 | H29: =IFERROR(__xludf.DUMMYFUNCTION("SUMIF($D$2:$D$530, TO_TEXT(F29) ,$C$2:$C$530)"),3000.0) -> 3000 | I29: TRUE | J29: =IF(I29=TRUE,0,MAX(G29-H29,0)) -> 0
B30: Đặt vé phim | C30: =401-85-85-85-85 -> 61 | D30: Living expense | F30: Trả tín dụng | G30: 1000 | H30: =IFERROR(__xludf.DUMMYFUNCTION("SUMIF($D$2:$D$530, TO_TEXT(F30) ,$C$2:$C$530)"),1000.0) -> 1000 | I30: TRUE | J30: =IF(I30=TRUE,0,MAX(G30-H30,0)) -> 0
B31: Ăn chiều | C31: 50 | D31: Living expense | F31: Shinhan | G31: 1700 | H31: =IFERROR(__xludf.DUMMYFUNCTION("SUMIF($D$2:$D$530, TO_TEXT(F31) ,$C$2:$C$530)"),1700.0) -> 1700 | I31: TRUE | J31: =IF(I31=TRUE,0,MAX(G31-H31,0)) -> 0
B32: Sữa | C32: 26 | D32: Living expense | F32: Tiền ăn ba má | G32: 5000 | H32: =IFERROR(__xludf.DUMMYFUNCTION("SUMIF($D$2:$D$530, TO_TEXT(F32) ,$C$2:$C$530)"),4500.0) -> 4500 | I32: TRUE | J32: =IF(I32=TRUE,0,MAX(G32-H32,0)) -> 0
B33: Bột chiên | C33: 70 | D33: Living expense | F33: Sức khỏe | G33: 800 | H33: =IFERROR(__xludf.DUMMYFUNCTION("SUMIF($D$2:$D$530, TO_TEXT(F33) ,$C$2:$C$530)"),338.0) -> 338 | I33: TRUE | J33: =IF(I33=TRUE,0,MAX(G33-H33,0)) -> 0
A34: 46238 | B34: Trà | C34: 18 | D34: Living expense | F34: Trả Khang | G34: 2000 | H34: =IFERROR(__xludf.DUMMYFUNCTION("SUMIF($D$2:$D$530, TO_TEXT(F34) ,$C$2:$C$530)"),2000.0) -> 2000 | I34: TRUE | J34: =IF(I34=TRUE,0,MAX(G34-H34,0)) -> 0
B35: Sữa | C35: 14 | D35: Living expense | F35: Trả chị Diễm | G35: 1000 | H35: =IFERROR(__xludf.DUMMYFUNCTION("SUMIF($D$2:$D$530, TO_TEXT(F35) ,$C$2:$C$530)"),1000.0) -> 1000 | I35: TRUE | J35: =IF(I35=TRUE,0,MAX(G35-H35,0)) -> 0
B36: Cơm gà | C36: =107-42 -> 65 | D36: Living expense
B37: Nước rạp phim | C37: =79-20-20 -> 39 | D37: Living expense
B38: Sữa | C38: 26 | D38: Living expense
A39: 46239 | B39: Trà | C39: 18 | D39: Living expense
B40: Bò kho | C40: 40 | D40: Living expense
...

Sheet T72026
A1: DATE | B1: SPENT FOR | C1: AMOUNT | D1: TYPE | F1: DATE | G1: EARN BY | H1: AMOUNT
A2: 46202 | B2: Mua vé Supergirl | C2: =271-75-75 -> 121 | D2: Living expense | F2: 46202 | G2: Lương T6 + Dư T6 | H2: =24357+42 -> 24399
B3: Help Ly sinh hoạt | C3: 2000 | D3: Help Ly | F3: 46205 | G3: Lương Ba | H3: 5545
B4: Bún cá T6 | C4: 55 | D4: Living expense | F4: 46218 | G4: Bảo gởi Gonsa | H4: 2000
B5: Nước ngọt | C5: 16 | D5: Living expense | G5: Khang support | H5: 2000
B6: Milo | C6: 48 | D6: Living expense | F6: 46224 | G6: Phúc | H6: 500
B7: Cho Má | C7: 5000 | D7: Tiền ăn ba má | F7: 46227 | G7: Bảo support | H7: 500
B8: Cơm trưa | C8: 37 | D8: Living expense | F8: 46228 | G8: Bảo support | H8: 300
B9: Order gỏi cuốn | C9: =111-25-24 -> 62 | D9: Living expense | G9: Mà cho | H9: 300
A10: 46203 | B10: Klara and The Sun Book | C10: 183 | D10: Living expense | F10: 46229 | G10: Mà cho | H10: 100
B11: Nước bình | C11: 160 | D11: Tiền nhà | F11: 46230 | G11: Rút tín dụng | H11: 1000
B12: KFC | C12: 111 | D12: Living expense
A13: 46204 | B13: Shinhan | C13: 1700 | D13: Shinhan | F13: Total earn | G13: =SUM(H2:H12) -> 36644
B14: Nước ngọt | C14: 16 | D14: Living expense | F14: Total spent | G14: =SUMPRODUCT(((D2:D231<>"Credit")*(D2:D231<>"Quỹ Shinhan"))*C2:C231) + G15 -> 36533
B15: Order gỏi cuốn | C15: =147-25-32-32 -> 58 | D15: Living expense | F15: Untrack spent | G15: =2+223+16+6+36+2+77+284-89+37+4 -> 598
A16: 46205 | B16: Milo | C16: 16 | D16: Living expense | F16: Saving | G16: 0
B17: Trả tín dụng | C17: 3000 | D17: Trả tín dụng
B18: Internet | C18: 164 | D18: Tiền nhà | F18: Remaining | G18: =G13-G14-J26 -> 111
B19: Tiền điện | C19: 805 | D19: Tiền nhà | F19: Remaining (- liabilities) | G19: =G13-G14 -> 111
A20: 46206 | B20: Ăn trưa | C20: 38 | D20: Living expense
B21: Relax Coffee | C21: 18 | D21: Living expense | F21: Category | G21: Estimated | H21: Actual
B22: Bò kho | C22: 40 | D22: Living expense | F22: Living expense | G22: 8000 | H22: =SUMIF(D2:D154, "=Living expense",C2:C172)+G15 -> 7335
B23: Circle K | C23: 30 | D23: Living expense
A24: 46207 | B24: Ăn trưa | C24: 245 | D24: Living expense | F24: Planned/actual spend per category of this month
B25: Khám bệnh Ba Má | C25: =200+76+68 -> 344 | D25: Sức khỏe | F25: Category | G25: Estimated | H25: Actual | I25: Finalize | J25: Reserve
B26: Ăn cơm với Má | C26: 78 | D26: Living expense | F26: Sum | G26: =SUM(G27:G108) -> 24900 | H26: =SUM(H27:H108) -> 27327 | J26: =SUM(J27:J108) -> 0
A27: 46208 | B27: Pizza | C27: 149 | D27: Living expense | F27: Tiền nhà | G27: 7200 | H27: =IFERROR(__xludf.DUMMYFUNCTION("SUMIF($D$2:$D$530, TO_TEXT(F27) ,$C$2:$C$530)"),7448.0) -> 7448 | I27: TRUE | J27: =IF(I27=TRUE,0,MAX(G27-H27,0)) -> 0
B28: Circle K | C28: 58 | D28: Living expense | F28: Gonsa | G28: 3000 | H28: =IFERROR(__xludf.DUMMYFUNCTION("SUMIF($D$2:$D$530, TO_TEXT(F28) ,$C$2:$C$530)"),5000.0) -> 5000 | I28: TRUE | J28: =IF(I28=TRUE,0,MAX(G28-H28,0)) -> 0
B29: Bún đậu | C29: 109 | D29: Living expense | F29: Help Ly | G29: 3500 | H29: =IFERROR(__xludf.DUMMYFUNCTION("SUMIF($D$2:$D$530, TO_TEXT(F29) ,$C$2:$C$530)"),3650.0) -> 3650 | I29: TRUE | J29: =IF(I29=TRUE,0,MAX(G29-H29,0)) -> 0
B30: Sách | C30: 251 | D30: Buy | F30: Trả tín dụng | G30: 3000 | H30: =IFERROR(__xludf.DUMMYFUNCTION("SUMIF($D$2:$D$530, TO_TEXT(F30) ,$C$2:$C$530)"),3000.0) -> 3000 | I30: TRUE | J30: =IF(I30=TRUE,0,MAX(G30-H30,0)) -> 0
A31: 46209 | B31: Ăn sáng | C31: 20 | D31: Living expense | F31: Shinhan | G31: 1700 | H31: =IFERROR(__xludf.DUMMYFUNCTION("SUMIF($D$2:$D$530, TO_TEXT(F31) ,$C$2:$C$530)"),1700.0) -> 1700 | I31: TRUE | J31: =IF(I31=TRUE,0,MAX(G31-H31,0)) -> 0
B32: Ăn trưa | C32: 32 | D32: Living expense | F32: Tiền ăn ba má | G32: 5000 | H32: =IFERROR(__xludf.DUMMYFUNCTION("SUMIF($D$2:$D$530, TO_TEXT(F32) ,$C$2:$C$530)"),5000.0) -> 5000 | I32: TRUE | J32: =IF(I32=TRUE,0,MAX(G32-H32,0)) -> 0
B33: Nước ngọt | C33: 16 | D33: Living expense | F33: Sức khỏe | G33: 1500 | H33: =IFERROR(__xludf.DUMMYFUNCTION("SUMIF($D$2:$D$530, TO_TEXT(F33) ,$C$2:$C$530)"),1529.0) -> 1529 | I33: TRUE | J33: =IF(I33=TRUE,0,MAX(G33-H33,0)) -> 0
B34: Order gỏi cuốn | C34: =108-36-36 -> 36 | D34: Living expense
B35: GO | C35: 1133 | D35: Living expense
B36: Nước ngọt | C36: 26 | D36: Living expense
A37: 46210 | B37: Ăn trưa | C37: 32 | D37: Living expense
B38: Trà đường | C38: 18 | D38: Living expense
B39: Order cơm chiều | C39: =132-30-30 -> 72 | D39: Living expense
A40: 46211 | B40: Ăn trưa | C40: 32 | D40: Living expense
...

Sheet T62026
A1: DATE | B1: SPENT FOR | C1: AMOUNT | D1: TYPE | F1: DATE | G1: EARN BY | H1: AMOUNT
A2: 46171 | B2: Cho Má | C2: 300 | D2: Living expense | F2: 46141 | G2: Lương T5 | H2: =24357 -> 24357
B3: Trả quỹ Shinhan | C3: 1000 | D3: Trả quỹ Shinhan | F3: 46177 | G3: Lương Ba | H3: 5545
B4: GS25 | C4: 16 | D4: Living expense | F4: 46178 | G4: Bảo trả Gonsa | H4: 1000
B5: Ăn trưa | C5: 32 | D5: Living expense | F5: 46180 | G5: Mượn quỹ Shinhan | H5: 2500
B6: Bún riêu cho Má | C6: 30 | D6: Parent | F6: 46188 | G6: Bảo gởi Gonsa | H6: 1500
B7: Circle K (khăn giấy, nước ngọt) | C7: 69 | D7: Living expense | F7: 46189 | G7: Gộp quỹ Shinhan | H7: =876+5850 -> 6726
B8: Trả Khang | C8: 2000 | D8: Trả Khang | G8: Futa hoàn tiền | H8: 864
B9: Trả tín dụng | C9: 3000 | D9: Trả tín dụng | F9: 46200 | G9: Bảo support | H9: 200
B10: Cho Má tiền ăn | C10: 5000 | D10: Tiền ăn ba má
A11: 46172 | B11: Xe ghép | C11: 190 | D11: Living expense
B12: Cơm Tuần Cường | C12: 27 | D12: Living expense
B13: Thùng xốp + gởi đồ cho Ly | C13: =120+280 -> 400 | D13: Support | F13: Total earn | G13: =SUM(H2:H12) -> 42692
B14: Bún bò | C14: 82 | D14: Living expense | F14: Total spent | G14: =SUMPRODUCT(((D2:D229<>"Credit")*(D2:D229<>"Quỹ Shinhan"))*C2:C229) + G15 -> 42650
B15: Taxi | C15: 96 | D15: Living expense | F15: Untrack spent | G15: =20+2+1749+36+146+122+124+119+52+75 -> 2445
B16: Nước | C16: 23 | D16: Living expense | F16: Saving | G16: 0
B17: Đồ chiên | C17: 50 | D17: Living expense
B18: Circle K | C18: 20 | D18: Living expense | F18: Remaining | G18: =G13-G14-J26 -> 42
A19: 46173 | B19: Ăn cơm trưa | C19: 30 | D19: Living expense | F19: Remaining (- liabilities) | G19: =G13-G14 -> 42
B20: Trà sữa | C20: 54 | D20: Living expense
B21: Đổ xăng | C21: 65 | D21: Living expense | F21: Category | G21: Estimated | H21: Actual
B22: Đổ xăng cho Ly | C22: 65 | D22: Support | F22: Living expense | G22: 8000 | H22: =SUMIF(D2:D152, "=Living expense",C2:C170)+G15 -> 10532
B23: GO | C23: 565 | D23: Credit
B24: Tiền kết | C24: 20 | D24: Living expense | F24: Planned/actual spend per category of this month
B25: Ăn chay | C25: 112 | D25: Living expense | F25: Category | G25: Estimated | H25: Actual | I25: Finalize | J25: Reserve
A26: 46174 | B26: GS25 | C26: 14 | D26: Living expense | F26: Sum | G26: =SUM(G27:G108) -> 25200 | H26: =SUM(H27:H108) -> 26789 | J26: =SUM(J27:J108) -> 0
B27: Order cơm chiều | C27: =108-36-36 -> 36 | D27: Living expense | F27: Tiền nhà | G27: 7000 | H27: =IFERROR(__xludf.DUMMYFUNCTION("SUMIF($D$2:$D$528, TO_TEXT(F27) ,$C$2:$C$528)"),6840.0) -> 6840 | I27: TRUE | J27: =IF(I27=TRUE,0,MAX(G27-H27,0)) -> 0
A28: 46175 | B28: Shinhan | C28: 1700 | D28: Shinhan | F28: Gonsa | G28: 3000 | H28: =IFERROR(__xludf.DUMMYFUNCTION("SUMIF($D$2:$D$528, TO_TEXT(F28) ,$C$2:$C$528)"),5000.0) -> 5000 | I28: TRUE | J28: =IF(I28=TRUE,0,MAX(G28-H28,0)) -> 0
B29: Tiền điện | C29: 990 | D29: Tiền nhà | F29: Trả Khang | G29: 2000 | H29: =IFERROR(__xludf.DUMMYFUNCTION("SUMIF($D$2:$D$528, TO_TEXT(F29) ,$C$2:$C$528)"),2000.0) -> 2000 | I29: TRUE | J29: =IF(I29=TRUE,0,MAX(G29-H29,0)) -> 0
B30: Party Rocket | C30: 231 | D30: Living expense | F30: Trả tín dụng | G30: 3000 | H30: =IFERROR(__xludf.DUMMYFUNCTION("SUMIF($D$2:$D$528, TO_TEXT(F30) ,$C$2:$C$528)"),3000.0) -> 3000 | I30: TRUE | J30: =IF(I30=TRUE,0,MAX(G30-H30,0)) -> 0
B31: Ăn chiều | C31: 442 | D31: Living expense | F31: Shinhan | G31: 1700 | H31: =IFERROR(__xludf.DUMMYFUNCTION("SUMIF($D$2:$D$528, TO_TEXT(F31) ,$C$2:$C$528)"),1700.0) -> 1700 | I31: TRUE | J31: =IF(I31=TRUE,0,MAX(G31-H31,0)) -> 0
B32: Circle K | C32: 92 | D32: Living expense | F32: Tiền ăn ba má | G32: 5000 | H32: =IFERROR(__xludf.DUMMYFUNCTION("SUMIF($D$2:$D$528, TO_TEXT(F32) ,$C$2:$C$528)"),5000.0) -> 5000 | I32: TRUE | J32: =IF(I32=TRUE,0,MAX(G32-H32,0)) -> 0
A33: 46176 | B33: Ăn trưa | C33: 32 | D33: Living expense | F33: Sức khỏe | G33: 1500 | H33: =IFERROR(__xludf.DUMMYFUNCTION("SUMIF($D$2:$D$528, TO_TEXT(F33) ,$C$2:$C$528)"),1249.0) -> 1249 | I33: TRUE | J33: =IF(I33=TRUE,0,MAX(G33-H33,0)) -> 0
B34: Nước ngọt | C34: 16 | D34: Living expense | F34: Trả quỹ Shinhan | G34: 1000 | H34: =IFERROR(__xludf.DUMMYFUNCTION("SUMIF($D$2:$D$528, TO_TEXT(F34) ,$C$2:$C$528)"),1000.0) -> 1000 | I34: TRUE | J34: =IF(I34=TRUE,0,MAX(G34-H34,0)) -> 0
B35: Order há cảo | C35: =183-61-61 -> 61 | D35: Living expense | F35: Trả quỹ Shinhan | G35: 1000 | H35: =IFERROR(__xludf.DUMMYFUNCTION("SUMIF($D$2:$D$528, TO_TEXT(F35) ,$C$2:$C$528)"),1000.0) -> 1000 | I35: TRUE | J35: =IF(I35=TRUE,0,MAX(G35-H35,0)) -> 0
B36: Ăn tối w/ Ly | C36: 96 | D36: Living expense
B37: Mua Aseprite tặng Ly (QP) | C37: 188 | D37: Credit
A38: 46177 | B38: Red Bull | C38: 24 | D38: Living expense
B39: Ăn chiều w/ Ly | C39: 60 | D39: Living expense
B40: Bánh tráng | C40: 37 | D40: Living expense
...

Sheet T52026
A1: DATE | B1: SPENT FOR | C1: AMOUNT | D1: TYPE | F1: DATE | G1: EARN BY | H1: AMOUNT
A2: 46140 | B2: Milo | C2: 20 | D2: Living expense | F2: 46140 | G2: Lương T4 + dư cuối T4 | H2: ='T42026'!G18+26920 -> 26989
B3: Ăn trưa | C3: 27 | D3: Living expense | G3: Lương Ba | H3: 5550
B4: Cơm | C4: 61 | D4: Living expense | F4: 46141 | G4: Thầy tặng | H4: 2000
B5: Cho Má | C5: 5000 | D5: Parent | G5: Má gởi lại | H5: 1000
A6: 46141 | B6: Help Bảo | C6: 2000 | D6: Help Bảo | F6: 46164 | G6: Bảo trả Gonsa | H6: 1000
B7: Trả Khang | C7: 3000 | D7: Trả Khang | G7: Mượn Quỹ Shinhan | H7: 3820
B8: Trả tín dụng | C8: 3000 | D8: Trả tín dụng
B9: Ăn trưa | C9: 28 | D9: Living expense
B10: Nước ngọt | C10: 16 | D10: Living expense
B11: Ăn chiều | C11: =107+10 -> 117 | D11: Living expense
A12: 46142 | B12: Jolibee | C12: 110 | D12: Living expense
B13: Trả chị Diễm | C13: 1000 | D13: Trả chị Diễm | F13: Total earn | G13: =SUM(H2:H12) -> 40359
B14: Trả tín dụng | C14: 1000 | D14: Trả tín dụng | F14: Total spent | G14: =SUMPRODUCT(((D2:D230<>"Credit")*(D2:D230<>"Qũy Shinhan"))*C2:C230) + G15 -> 40359
B15: Mua máy cạo | C15: 525 | D15: Buy | F15: Untrack spent | G15: =1+245+383+38+92-37+1+77 -> 800
B16: Ăn tối | C16: =30+52 -> 82 | D16: Living expense | F16: Saving | G16: 0
A17: 46143 | B17: Ăn chiều | C17: =30+20 -> 50 | D17: Living expense
B18: Cháo cho Ba | C18: 17 | D18: Living expense | F18: Remaining | G18: =G13-G14-J26 -> 0
A19: 46144 | B19: Gởi Má khám bệnh | C19: 3000 | D19: Khám bệnh cho Má | F19: Remaining (- liabilities) | G19: =G13-G14 -> 0
B20: Ăn trưa | C20: 30 | D20: Living expense
B21: Circle K | C21: 14 | D21: Living expense | F21: Category | G21: Estimated | H21: Actual
B22: Cháo cho Ba | C22: 22 | D22: Living expense | F22: Living expense | G22: 8000 | H22: =SUMIF(D2:D153, "=Living expense",C2:C171)+G15 -> 7440
B23: Jolibee | C23: 85 | D23: Living expense
B24: Pizza | C24: 103 | D24: Living expense | F24: Planned/actual spend per category of this month
B25: Tiền điện | C25: =26+845 -> 871 | D25: Tiền nhà | F25: Category | G25: Estimated | H25: Actual | I25: Finalize | J25: Reserve
A26: 46145 | B26: Cơm cho Má | C26: 40 | D26: Living expense | F26: Sum | G26: =SUM(G27:G108) -> 25871 | H26: =SUM(H27:H108) -> 31116 | J26: =SUM(J27:J108) -> 0
B27: Salon | C27: 315 | D27: Living expense | F27: Tiền nhà | G27: 6871 | H27: =IFERROR(__xludf.DUMMYFUNCTION("SUMIF($D$2:$D$529, TO_TEXT(F27) ,$C$2:$C$529)"),6980.0) -> 6980 | I27: TRUE | J27: =IF(I27=TRUE,0,MAX(G27-H27,0)) -> 0
B28: Rửa xe | C28: 30 | D28: Living expense | F28: Gonsa | G28: 3000 | H28: =IFERROR(__xludf.DUMMYFUNCTION("SUMIF($D$2:$D$529, TO_TEXT(F28) ,$C$2:$C$529)"),5000.0) -> 5000 | I28: TRUE | J28: =IF(I28=TRUE,0,MAX(G28-H28,0)) -> 0
B29: Bách hóa Xanh | C29: 117 | D29: Living expense | F29: Trả Khang | G29: 3000 | H29: =IFERROR(__xludf.DUMMYFUNCTION("SUMIF($D$2:$D$529, TO_TEXT(F29) ,$C$2:$C$529)"),3000.0) -> 3000 | I29: TRUE | J29: =IF(I29=TRUE,0,MAX(G29-H29,0)) -> 0
B30: Tiền kết | C30: 20 | D30: Living expense | F30: Trả tín dụng | G30: 3000 | H30: =IFERROR(__xludf.DUMMYFUNCTION("SUMIF($D$2:$D$529, TO_TEXT(F30) ,$C$2:$C$529)"),4000.0) -> 4000 | I30: TRUE | J30: =IF(I30=TRUE,0,MAX(G30-H30,0)) -> 0
B31: Bột chiên | C31: 60 | D31: Living expense | F31: Parent | G31: 5000 | H31: =IFERROR(__xludf.DUMMYFUNCTION("SUMIF($D$2:$D$529, TO_TEXT(F31) ,$C$2:$C$529)"),5636.0) -> 5636 | I31: TRUE | J31: =IF(I31=TRUE,0,MAX(G31-H31,0)) -> 0
A32: 46146 | B32: Ăn khuya | C32: 80 | D32: Living expense | F32: Trả chị Diễm | G32: 1000 | H32: =IFERROR(__xludf.DUMMYFUNCTION("SUMIF($D$2:$D$529, TO_TEXT(F32) ,$C$2:$C$529)"),1500.0) -> 1500 | I32: TRUE | J32: =IF(I32=TRUE,0,MAX(G32-H32,0)) -> 0
B33: Ăn trưa | C33: 27 | D33: Living expense | F33: Khám bệnh cho Má | G33: 3000 | H33: =IFERROR(__xludf.DUMMYFUNCTION("SUMIF($D$2:$D$529, TO_TEXT(F33) ,$C$2:$C$529)"),3000.0) -> 3000 | I33: TRUE | J33: =IF(I33=TRUE,0,MAX(G33-H33,0)) -> 0
B34: Sữa milo | C34: 20 | D34: Living expense | F34: Help Bảo | G34: 1000 | H34: =IFERROR(__xludf.DUMMYFUNCTION("SUMIF($D$2:$D$529, TO_TEXT(F34) ,$C$2:$C$529)"),2000.0) -> 2000 | I34: TRUE | J34: =IF(I34=TRUE,0,MAX(G34-H34,0)) -> 0
B35: Bột chiên | C35: 54 | D35: Living expense
A36: 46147 | B36: Ăn trưa | C36: 38 | D36: Living expense
B37: Milo | C37: 20 | D37: Living expense
B38: Bún riêu cho Má | C38: 30 | D38: Parent
B39: Jolibee | C39: 96 | D39: Living expense
B40: Trả chị Diễm | C40: 500 | D40: Trả chị Diễm
...

Sheet T42026
A1: DATE | B1: SPENT FOR | C1: AMOUNT | D1: TYPE | F1: DATE | G1: EARN BY | H1: AMOUNT
A2: 46111 | B2: Cơm gà Lê Trang | C2: =131-38-34 -> 59 | D2: Living expense | F2: 46111 | G2: Lương T3 + dư cuối T3 | H2: =24357+'T32026'!G18 -> 24646
B3: Help Nhi | C3: 100 | D3: Living expense | G3: Má gởi | H3: 50
B4: Trả Tú pizza, nước | C4: 82 | D4: Living expense | F4: 46116 | G4: Lương Ba | H4: 5590
B5: Gym | C5: 30 | D5: Living expense | F5: 46129 | G5: Khang help | H5: 1000
B6: Bún riêu | C6: 25 | D6: Living expense | F6: 46130 | G6: Bảo trả | H6: 500
B7: Trả tín dụng | C7: 2500 | D7: Trả tín dụng | F7: 46134 | G7: Bảo trả | H7: 500
B8: Trả Khang | C8: 3000 | D8: Trả Khang | F8: 46136 | G8: Thầy Thái gởi thuế | H8: 3000
B9: Cho Má | C9: 4000 | D9: Parent | F9: 46137 | G9: Khang help | H9: 1000
A10: 46112 | B10: Cà phê | C10: 22 | D10: Living expense
B11: Order gỏi cuốn | C11: =147-35-42-35 -> 35 | D11: Living expense
B12: Siêu thị | C12: 834 | D12: Living expense
B13: Texas | C13: 123 | D13: Living expense | F13: Total earn | G13: =SUM(H2:H12) -> 36286
B14: Cơm trưa | C14: 38 | D14: Living expense | F14: Total spent | G14: =SUMIF(D2:D228, "<>Credit", C2:C536) + G15 -> 36217
B15: Trả chị Diễm | C15: 1000 | D15: Trả chị Diễm | F15: Untrack spent | G15: =282+43-71+42+3+7+170 -> 476
A16: 46113 | B16: GS25 | C16: 15 | D16: Living expense | F16: Saving | G16: 0
B17: Cơm | C17: 38 | D17: Living expense
B18: Order cơm gà | C18: =179-33-44-33-35 -> 34 | D18: Living expense | F18: Remaining | G18: =G13-G14-J26 -> 69
B19: Kem | C19: 40 | D19: Living expense | F19: Remaining (- liabilities) | G19: =G13-G14 -> 69
A20: 46114 | B20: GS25 | C20: 15 | D20: Living expense
B21: Cơm trưa | C21: 38 | D21: Living expense | F21: Category | G21: Estimated | H21: Actual
B22: Tiền điện | C22: 497 | D22: Tiền nhà | F22: Living expense | G22: 8000 | H22: =SUMIF(D2:D151, "=Living expense",C2:C169)+G15 -> 9287
B23: Tiền kết | C23: 13 | D23: Living expense
B24: Jolibee | C24: 110 | D24: Living expense | F24: Planned/actual spend per category of this month
B25: Đổ xăng | C25: 50 | D25: Living expense | F25: Category | G25: Estimated | H25: Actual | I25: Finalize | J25: Reserve
A26: 46115 | B26: Help Ly | C26: 1000 | D26: Living expense | F26: Sum | G26: =SUM(G27:G107) -> 20000 | H26: =SUM(H27:H107) -> 23577 | J26: =SUM(J27:J107) -> 0
B27: Ăn trưa | C27: 35 | D27: Living expense | F27: Tiền nhà | G27: 6500 | H27: =IFERROR(__xludf.DUMMYFUNCTION("SUMIF($D$2:$D$527, TO_TEXT(F27) ,$C$2:$C$527)"),6606.0) -> 6606 | I27: TRUE | J27: =IF(I27=TRUE,0,MAX(G27-H27,0)) -> 0
B28: GS25 | C28: 15 | D28: Living expense | F28: Gonsa | G28: 3000 | H28: =IFERROR(__xludf.DUMMYFUNCTION("SUMIF($D$2:$D$527, TO_TEXT(F28) ,$C$2:$C$527)"),5000.0) -> 5000 | I28: TRUE | J28: =IF(I28=TRUE,0,MAX(G28-H28,0)) -> 0
B29: Ăn tối | C29: 114 | D29: Living expense | F29: Trả Khang | G29: 3000 | H29: =IFERROR(__xludf.DUMMYFUNCTION("SUMIF($D$2:$D$527, TO_TEXT(F29) ,$C$2:$C$527)"),3000.0) -> 3000 | I29: TRUE | J29: =IF(I29=TRUE,0,MAX(G29-H29,0)) -> 0
B30: FShare | C30: 90 | D30: Living expense | F30: Trả tín dụng | G30: 2500 | H30: =IFERROR(__xludf.DUMMYFUNCTION("SUMIF($D$2:$D$527, TO_TEXT(F30) ,$C$2:$C$527)"),2500.0) -> 2500 | I30: TRUE | J30: =IF(I30=TRUE,0,MAX(G30-H30,0)) -> 0
B31: Circle K | C31: 70 | D31: Living expense | F31: Parent | G31: 4000 | H31: =IFERROR(__xludf.DUMMYFUNCTION("SUMIF($D$2:$D$527, TO_TEXT(F31) ,$C$2:$C$527)"),4971.0) -> 4971 | I31: TRUE | J31: =IF(I31=TRUE,0,MAX(G31-H31,0)) -> 0
A32: 46116 | B32: Cơm | C32: 30 | D32: Living expense | F32: Trả chị Diễm | G32: 1000 | H32: =IFERROR(__xludf.DUMMYFUNCTION("SUMIF($D$2:$D$527, TO_TEXT(F32) ,$C$2:$C$527)"),1500.0) -> 1500 | I32: TRUE | J32: =IF(I32=TRUE,0,MAX(G32-H32,0)) -> 0
B33: Hớt tóc | C33: 235 | D33: Living expense
B34: Phim | C34: 145 | D34: Living expense
B35: Texas | C35: 119 | D35: Living expense
B36: Trả chị Diễm | C36: 500 | D36: Trả chị Diễm
A37: 46117 | B37: Tiền kết | C37: 20 | D37: Living expense
B38: Ăn tối | C38: 110 | D38: Living expense
A39: 46118 | B39: Remote | C39: 200 | D39: Tiền nhà
B40: Bún đậu | C40: 107 | D40: Living expense
...

Sheet T32026
A1: DATE | B1: SPENT FOR | C1: AMOUNT | D1: TYPE | F1: DATE | G1: EARN BY | H1: AMOUNT
A2: 46080 | B2: ShopeeFood | C2: 0 | D2: Living expense | F2: 46080 | G2: Lương T2 + dư cuối T1 | H2: =57+24357+146-200 -> 24360
B3: Ăn cơm trưa | C3: 50 | D3: Living expense | G3: A Trung lì xì | H3: 200
B4: Ăn cơm chiều | C4: 60 | D4: Living expense | F4: 46081 | G4: Shopee hoàn tiền | H4: 281
B5: Cho Má | C5: 5000 | D5: Parent | F5: 46084 | G5: Papaya hoàn tiền | H5: 3150
B6: Bò kho | C6: 80 | D6: Living expense | F6: 46086 | G6: Lương của Ba | H6: 5545
B7: Thuốc | C7: 183 | D7: Living expense | F7: 46096 | G7: Khang support | H7: 3000
B8: Circle K | C8: 182 | D8: Living expense | F8: 46102 | G8: Khang support | H8: 3000
B9: Help Ly | C9: 500 | D9: Support | G9: Bảo trả | H9: =500+1300 -> 1800
A10: 46081 | B10: Cơm niêu | C10: 205 | D10: Living expense | F10: 46108 | G10: Bảo support | H10: 200
B11: LEGO | C11: 938 | D11: Living expense
B12: Trả tín dung | C12: 4292 | D12: Trả tín dụng
B13: Trả Khang | C13: 2945 | D13: Trả Khang | F13: Total earn | G13: =SUM(H2:H12) -> 41536
B14: Siêu thị | C14: =50+180+620+590 -> 1440 | D14: Living expense | F14: Total spent | G14: =SUMIF(D2:D228, "<>Credit", C2:C536) + G15 -> 41247
B15: Mua quạt | C15: 390 | D15: Living expense | F15: Untrack spent | G15: =69 -> 69
B16: Trả chị Diễm | C16: 2000 | D16: Trả chị Diễm | F16: Saving | G16: 0
A17: 46082 | B17: Đổ xăng | C17: 50 | D17: Living expense
B18: 30Shine | C18: 459 | D18: Living expense | F18: Remaining | G18: =G13-G14-J26 -> 289
B19: Tiền kết | C19: 20 | D19: Living expense | F19: Remaining (- liabilities) | G19: =G13-G14 -> 289
B20: Hot dog | C20: 30 | D20: Living expense
B21: Netflix | C21: 273 | D21: Living expense | F21: Category | G21: Estimated | H21: Actual
A22: 46083 | B22: Sữa milo | C22: 20 | D22: Living expense | F22: Living expense | G22: 8000 | H22: =SUMIF(D2:D151, "=Living expense",C2:C169)+G15 -> 10930
B23: Order há cảo | C23: 73 | D23: Living expense
A24: 46084 | B24: Tiền điện Trà Vinh | C24: 19 | D24: Tiền nhà | F24: Planned/actual spend per category of this month
B25: Tiền điện Cần Thơ | C25: 312 | D25: Tiền nhà | F25: Category | G25: Estimated | H25: Actual | I25: Finalize | J25: Reserve
B26: GS25 | C26: 18 | D26: Living expense | F26: Sum | G26: =SUM(G27:G107) -> 23737 | H26: =SUM(H27:H107) -> 29717 | J26: =SUM(J27:J107) -> 0
B27: Ăn tối với Má | C27: 235 | D27: Living expense | F27: Tiền nhà | G27: 6500 | H27: =IFERROR(__xludf.DUMMYFUNCTION("SUMIF($D$2:$D$527, TO_TEXT(F27) ,$C$2:$C$527)"),6431.0) -> 6431 | I27: TRUE | J27: =IF(I27=TRUE,0,MAX(G27-H27,0)) -> 0
B28: Order cơm ếch | C28: =145-45-50 -> 50 | D28: Living expense | F28: Gonsa | G28: 3000 | H28: =IFERROR(__xludf.DUMMYFUNCTION("SUMIF($D$2:$D$527, TO_TEXT(F28) ,$C$2:$C$527)"),5000.0) -> 5000 | I28: TRUE | J28: =IF(I28=TRUE,0,MAX(G28-H28,0)) -> 0
A29: 46085 | B29: Ăn trưa | C29: 45 | D29: Living expense | F29: Trả Khang | G29: 2945 | H29: =IFERROR(__xludf.DUMMYFUNCTION("SUMIF($D$2:$D$527, TO_TEXT(F29) ,$C$2:$C$527)"),2945.0) -> 2945 | I29: TRUE | J29: =IF(I29=TRUE,0,MAX(G29-H29,0)) -> 0
B30: GS25 | C30: 10 | D30: Living expense | F30: Trả tín dụng | G30: 4292 | H30: =IFERROR(__xludf.DUMMYFUNCTION("SUMIF($D$2:$D$527, TO_TEXT(F30) ,$C$2:$C$527)"),4292.0) -> 4292 | I30: TRUE | J30: =IF(I30=TRUE,0,MAX(G30-H30,0)) -> 0
B31: Jolibee | C31: 103 | D31: Living expense | F31: Parent | G31: 5000 | H31: =IFERROR(__xludf.DUMMYFUNCTION("SUMIF($D$2:$D$527, TO_TEXT(F31) ,$C$2:$C$527)"),9049.0) -> 9049 | I31: TRUE | J31: =IF(I31=TRUE,0,MAX(G31-H31,0)) -> 0
A32: 46086 | B32: Thuốc | C32: 41 | D32: Living expense | F32: Trả chị Diễm | G32: 2000 | H32: =IFERROR(__xludf.DUMMYFUNCTION("SUMIF($D$2:$D$527, TO_TEXT(F32) ,$C$2:$C$527)"),2000.0) -> 2000 | I32: TRUE | J32: =IF(I32=TRUE,0,MAX(G32-H32,0)) -> 0
B33: GS25 | C33: 38 | D33: Living expense
B34: Mua đồ lăn lông áo | C34: 118 | D34: Living expense
B35: Bún riêu | C35: 25 | D35: Living expense
B36: Sandwich | C36: 31 | D36: Living expense
A37: 46087 | B37: Minecraft cards | C37: 232 | D37: Living expense
B38: Ăn trưa | C38: =90-30-30 -> 30 | D38: Living expense
B39: GS25 | C39: 43 | D39: Living expense
B40: Order há cáo | C40: =172-30-30-23-46 -> 43 | D40: Living expense
...

Sheet T22026
A1: DATE | B1: SPENT FOR | C1: AMOUNT | D1: TYPE | F1: DATE | G1: EARN BY | H1: AMOUNT
A2: 46051 | B2: Trà | C2: 12 | D2: Living expense | F2: 46051 | G2: Lương T1 | H2: =21691+65 -> 21756
B3: Ăn chiều | C3: 65 | D3: Living expense | F3: 46053 | G3: JICA Bonus | H3: 4000
B4: Cho Má | C4: 3000 | D4: Cho Má + lì xì | F4: 46054 | G4: Bảo trả | H4: 300
A5: 46052 | B5: Ăn trưa quán nước | C5: 0 | D5: Living expense | F5: 46058 | G5: Lương thưởng | H5: 21235
B6: Đám cưới anh Nghĩa | C6: 500 | D6: Đám cưới | F6: 46060 | G6: Lương Ba | H6: 5545
B7: Jolibee | C7: 83 | D7: Living expense | F7: 46064 | G7: Rút tín dụng | H7: 12000
B8: Trả tín dụng | C8: 2500 | D8: Tín dụng | F8: 46068 | G8: Bảo gởi | H8: 1500
B9: Trả máy hút bụi | C9: 500 | D9: Trả máy hút bụi | F9: 46069 | G9: Bạn của Ba giúp | H9: 1800
B10: Giúp chi hội | C10: 1000 | D10: Giúp chi hội | F10: 46070 | G10: Lì xì | H10: 100
B11: Trả Khang | C11: 1000 | D11: Trả Khang | F11: 46074 | G11: Rút tín dụng | H11: 1500
A12: 46053 | B12: Khám bệnh cho Má | C12: =120+2000+539+640 -> 3299 | D12: Khám bệnh cho Má | F12: 46076 | G12: A Ngộ lì xì | H12: 100
B13: Ăn phở | C13: 100 | D13: Living expense | F13: Total earn | G13: =SUM(H2:H12) -> 69836
B14: Bún đậu | C14: 109 | D14: Living expense | F14: Total spent | G14: =SUMIF(D2:D221, "<>Credit", C2:C529) + G15 -> 69779
B15: Bánh tráng | C15: 65 | D15: Living expense | F15: Untrack spent | G15: =5+359+57-37+5+541+41 -> 971
B16: Winmart+ | C16: 548 | D16: Living expense | F16: Saving | G16: 0
B17: Sâm bổ | C17: 110 | D17: Living expense
B18: Trả chị Diễm | C18: 5000 | D18: Trả chị Diễm | F18: Remaining | G18: =G13-G14-J26 -> 57
B19: Dây đồng hồ | C19: 26 | D19: Living expense | F19: Remaining (- liabilities) | G19: =G13-G14 -> 57
A20: 46054 | B20: Help Nguyệt | C20: 3000 | D20: Support
B21: Cơm niêu | C21: 205 | D21: Living expense | F21: Category | G21: Estimated | H21: Actual
B22: Đổ xăng | C22: 50 | D22: Living expense | F22: Living expense | G22: 8000 | H22: =SUMIF(D2:D144, "=Living expense",C2:C162)+G15 -> 12898
B23: Winmart | C23: 572 | D23: Credit
B24: Minecraft mod | C24: 219 | D24: Living expense | F24: Planned/actual spend per category of this month
B25: Ăn tối | C25: 60 | D25: Living expense | F25: Category | G25: Estimated | H25: Actual | I25: Finalize | J25: Reserve
A26: 46055 | B26: Nước | C26: 7 | D26: Living expense | F26: Sum | G26: =SUM(G27:G104) -> 32620 | H26: =SUM(H27:H104) -> 50662 | J26: =SUM(J27:J104) -> 0
B27: Điện Trà Vinh | C27: 15 | D27: Tiền nhà | F27: Tiền nhà | G27: 6400 | H27: =IFERROR(__xludf.DUMMYFUNCTION("SUMIF($D$2:$D$520, TO_TEXT(F27) ,$C$2:$C$520)"),6424.0) -> 6424 | I27: TRUE | J27: =IF(I27=TRUE,0,MAX(G27-H27,0)) -> 0
B28: Điện Cần Thơ | C28: 300 | D28: Tiền nhà | F28: Cho Má + lì xì | G28: 7000 | H28: =IFERROR(__xludf.DUMMYFUNCTION("SUMIF($D$2:$D$520, TO_TEXT(F28) ,$C$2:$C$520)"),7330.0) -> 7330 | I28: TRUE | J28: =IF(I28=TRUE,0,MAX(G28-H28,0)) -> 0
B29: Trả a Khoa | C29: 16 | D29: Living expense | F29: Trả chị Diễm | G29: 5000 | H29: =IFERROR(__xludf.DUMMYFUNCTION("SUMIF($D$2:$D$520, TO_TEXT(F29) ,$C$2:$C$520)"),5000.0) -> 5000 | I29: TRUE | J29: =IF(I29=TRUE,0,MAX(G29-H29,0)) -> 0
B30: Trả Toàn | C30: 33 | D30: Living expense | F30: Gonsa | G30: 4500 | H30: =IFERROR(__xludf.DUMMYFUNCTION("SUMIF($D$2:$D$520, TO_TEXT(F30) ,$C$2:$C$520)"),5000.0) -> 5000 | I30: TRUE | J30: =IF(I30=TRUE,0,MAX(G30-H30,0)) -> 0
B31: Ăn chiều | C31: 52 | D31: Living expense | F31: Tín dụng | G31: 2500 | H31: =IFERROR(__xludf.DUMMYFUNCTION("SUMIF($D$2:$D$520, TO_TEXT(F31) ,$C$2:$C$520)"),17500.0) -> 17500 | I31: TRUE | J31: =IF(I31=TRUE,0,MAX(G31-H31,0)) -> 0
A32: 46056 | B32: Ăn trưa | C32: 30 | D32: Living expense | F32: Lì xì | G32: 2000 | H32: =IFERROR(__xludf.DUMMYFUNCTION("SUMIF($D$2:$D$520, TO_TEXT(F32) ,$C$2:$C$520)"),2300.0) -> 2300 | I32: TRUE | J32: =IF(I32=TRUE,0,MAX(G32-H32,0)) -> 0
A33: 46057 | B33: KitKat | C33: 24 | D33: Living expense | F33: Khám bệnh cho Ba | G33: 1000 | H33: =IFERROR(__xludf.DUMMYFUNCTION("SUMIF($D$2:$D$520, TO_TEXT(F33) ,$C$2:$C$520)"),89.0) -> 89 | I33: TRUE | J33: =IF(I33=TRUE,0,MAX(G33-H33,0)) -> 0
B34: Order há cáo | C34: =184-33-33-37-37 -> 44 | D34: Living expense | F34: Trả Khang | G34: 1000 | H34: =IFERROR(__xludf.DUMMYFUNCTION("SUMIF($D$2:$D$520, TO_TEXT(F34) ,$C$2:$C$520)"),1000.0) -> 1000 | I34: TRUE | J34: =IF(I34=TRUE,0,MAX(G34-H34,0)) -> 0
B35: Jolibee | C35: 83 | D35: Living expense | F35: Giúp chi hội | G35: 1000 | H35: =IFERROR(__xludf.DUMMYFUNCTION("SUMIF($D$2:$D$520, TO_TEXT(F35) ,$C$2:$C$520)"),1000.0) -> 1000 | I35: TRUE | J35: =IF(I35=TRUE,0,MAX(G35-H35,0)) -> 0
B36: WiFi | C36: 720 | D36: Wifi | F36: Wifi | G36: 720 | H36: =IFERROR(__xludf.DUMMYFUNCTION("SUMIF($D$2:$D$520, TO_TEXT(F36) ,$C$2:$C$520)"),720.0) -> 720 | I36: TRUE | J36: =IF(I36=TRUE,0,MAX(G36-H36,0)) -> 0
A37: 46058 | B37: Sữa trái cây | C37: 12 | D37: Living expense | F37: Trả máy hút bụi | G37: 500 | H37: =IFERROR(__xludf.DUMMYFUNCTION("SUMIF($D$2:$D$520, TO_TEXT(F37) ,$C$2:$C$520)"),500.0) -> 500 | I37: TRUE | J37: =IF(I37=TRUE,0,MAX(G37-H37,0)) -> 0
B38: Bách hóa Xanh | C38: 40 | D38: Living expense | F38: Phụ mua đồ ăn nhà mợ Hai | G38: 500 | H38: =IFERROR(__xludf.DUMMYFUNCTION("SUMIF($D$2:$D$520, TO_TEXT(F38) ,$C$2:$C$520)"),0.0) -> 0 | I38: TRUE | J38: =IF(I38=TRUE,0,MAX(G38-H38,0)) -> 0
B39: Súp | C39: 30 | D39: Living expense | F39: Đám cưới | G39: 500 | H39: =IFERROR(__xludf.DUMMYFUNCTION("SUMIF($D$2:$D$520, TO_TEXT(F39) ,$C$2:$C$520)"),500.0) -> 500 | I39: TRUE | J39: =IF(I39=TRUE,0,MAX(G39-H39,0)) -> 0
B40: Thuốc cho Má | C40: 112 | D40: Living expense | F40: Khám bệnh cho Má | G40: 0 | H40: =IFERROR(__xludf.DUMMYFUNCTION("SUMIF($D$2:$D$520, TO_TEXT(F40) ,$C$2:$C$520)"),3299.0) -> 3299 | I40: TRUE | J40: =IF(I40=TRUE,0,MAX(G40-H40,0)) -> 0
...

Sheet T12026
A1: DATE | B1: SPENT FOR | C1: AMOUNT | D1: TYPE | F1: DATE | G1: EARN BY | H1: AMOUNT
A2: 46021 | B2: Trả party Rocket | C2: 200 | D2: Living expense | F2: 45991 | G2: Lương T12 | H2: =23419 -> 23419
B3: Trả Credit | C3: 8000 | D3: Credit debt | F3: 46024 | G3: Lương Ba | H3: 5540
B4: Trả Khang | C4: 2000 | D4: Khang debt | F4: 46034 | G4: Credit | H4: 11000
B5: Cho Má | C5: 3000 | D5: Parent | F5: 46038 | G5: Lương Ba | H5: 5550
B6: Ăn tối | C6: 64 | D6: Living expense | F6: 46042 | G6: Bảo gởi | H6: 200
A7: 46022 | B7: Nước ngọt | C7: 14 | D7: Living expense | F7: 46044 | G7: Bảo gởi | H7: 300
B8: Trả a Khoa | C8: 36 | D8: Living expense | F8: 46045 | G8: Bảo gởi | H8: 130
B9: Gỏi cuốn | C9: 35 | D9: Living expense | F9: 46046 | G9: Bảo gởi | H9: 370
B10: Fahasha | C10: 340 | D10: Buy | F10: 46049 | G10: Bảo gởi | H10: 400
B11: Jolibee | C11: 138 | D11: Living expense
A12: 46023 | B12: Taxi | C12: 1266 | D12: Travel
B13: Fahasha | C13: 19 | D13: Living expense | F13: Total earn | G13: =SUM(H2:H12) -> 46909
B14: Thuốc cho Ba | C14: 489 | D14: Parent | F14: Total spent | G14: =SUMIF(D2:D225, "<>Credit", C2:C533) + G15 -> 46844
B15: Help Ly | C15: 2000 | D15: Help Ly | F15: Untrack spent | G15: =242+50+22+257+62+262 -> 895
B16: Jolibee | C16: =176+17 -> 193 | D16: Living expense | F16: Saving | G16: 0
A17: 46024 | B17: Ăn sáng | C17: 60 | D17: Living expense
B18: Vớ | C18: 50 | D18: Living expense | F18: Remaining | G18: =G13-G14-J33 -> 65
B19: Winmart | C19: 202 | D19: Parent | F19: Remaining (- liabilities) | G19: =G13-G14 -> 65
B20: Dép cho Má | C20: 225 | D20: Parent
B21: Massage | C21: 150 | D21: Living expense | F21: Category | G21: Estimated | H21: Actual
B22: Massage Má | C22: 150 | D22: Parent | F22: Living expense | G22: 5000 | H22: =SUMIF(D2:D148, "=Living expense",C2:C166)+G15 -> 6674
B23: Bột chiên | C23: 30 | D23: Living expense
B24: Nhanh Thạch | C24: 100 | D24: Living expense | F24: Planned/actual spend per category of this month
B25: Hớt tóc cho Ba | C25: 35 | D25: Parent | F25: Category | G25: Estimated | H25: Actual | I25: Finalize | J25: Reserve
B26: Ăn cơm với Má | C26: 50 | D26: Living expense | F26: Gonsa | G26: 3000 | H26: =IFERROR(__xludf.DUMMYFUNCTION("SUMIF($D$2:$D$524, TO_TEXT(F26) ,$C$2:$C$524)"),5000.0) -> 5000 | I26: TRUE | J26: =IF(I26=TRUE,0,MAX(G26-H26,0)) -> 0
A27: 46025 | B27: Cơm gà | C27: 25 | D27: Living expense | F27: Rent | G27: 6600 | H27: =IFERROR(__xludf.DUMMYFUNCTION("SUMIF($D$2:$D$524, TO_TEXT(F27) ,$C$2:$C$524)"),6622.0) -> 6622 | I27: TRUE | J27: =IF(I27=TRUE,0,MAX(G27-H27,0)) -> 0
B28: Đổ xăng | C28: 42 | D28: Living expense | F28: Parent | G28: 3000 | H28: =IFERROR(__xludf.DUMMYFUNCTION("SUMIF($D$2:$D$524, TO_TEXT(F28) ,$C$2:$C$524)"),8754.0) -> 8754 | I28: TRUE | J28: =IF(I28=TRUE,0,MAX(G28-H28,0)) -> 0
B29: Cà phê | C29: 47 | D29: Living expense | F29: Credit debt | G29: 18000 | H29: =IFERROR(__xludf.DUMMYFUNCTION("SUMIF($D$2:$D$524, TO_TEXT(F29) ,$C$2:$C$524)"),11000.0) -> 11000 | I29: TRUE | J29: =IF(I29=TRUE,0,MAX(G29-H29,0)) -> 0
B30: Taxi | C30: =103+34+98 -> 235 | D30: Travel | F30: Travel | G30: 2000 | H30: =IFERROR(__xludf.DUMMYFUNCTION("SUMIF($D$2:$D$524, TO_TEXT(F30) ,$C$2:$C$524)"),2468.0) -> 2468 | I30: TRUE | J30: =IF(I30=TRUE,0,MAX(G30-H30,0)) -> 0
B31: Thuốc cho Má | C31: 17 | D31: Parent | F31: Khang debt | G31: 2000 | H31: =IFERROR(__xludf.DUMMYFUNCTION("SUMIF($D$2:$D$524, TO_TEXT(F31) ,$C$2:$C$524)"),2000.0) -> 2000 | I31: TRUE | J31: =IF(I31=TRUE,0,MAX(G31-H31,0)) -> 0
B32: Nhanh Thạch | C32: 15 | D32: Living expense | F32: Help Ly | G32: 2000 | H32: =IFERROR(__xludf.DUMMYFUNCTION("SUMIF($D$2:$D$524, TO_TEXT(F32) ,$C$2:$C$524)"),3000.0) -> 3000 | I32: TRUE | J32: =IF(I32=TRUE,0,MAX(G32-H32,0)) -> 0
B33: Tiền điện | C33: 533 | D33: Rent | F33: Sum | G33: =SUM(G27:G30) -> 29600 | H33: =SUM(H27:H29) -> 26376 | J33: =SUM(J26:J32) -> 0
A34: 46026 | B34: Thuốc đau đầu | C34: 17 | D34: Living expense
B35: Thuốc huyết áp | C35: 27 | D35: Living expense
B36: Taxi | C36: 967 | D36: Travel
B37: Cơm chiều | C37: 25 | D37: Living expense
B38: Cháo | C38: 30 | D38: Living expense
A39: 46027 | B39: Súp | C39: 11 | D39: Living expense
B40: Đổ xăng | C40: 48 | D40: Living expense
...

Sheet T122025
A1: DATE | B1: SPENT FOR | C1: AMOUNT | D1: TYPE | F1: DATE | G1: EARN BY | H1: AMOUNT
A2: 45988 | B2: Sữa | C2: 11 | D2: Living expense | F2: 45988 | G2: Cuối T11 | H2: ='T112025'!G19 -> 419
B3: Trả Khang | C3: 1000 | D3: Khang debt | G3: Lương T11 | H3: 23500
B4: Quà tặng thầy Thái | C4: 275 | D4: Khang debt | F4: 45989 | G4: Bảo gởi tiền cưới | H4: 1000
B5: Ăn tối | C5: 50 | D5: Living expense | F5: 46000 | G5: Khang support | H5: 3000
B6: Thuốc | C6: 101 | D6: Living expense | G6: Credit | H6: 5000
B7: Cho Má | C7: 4000 | D7: Parent | F7: 46002 | G7: Credit | H7: 10000
B8: Trả Credit Kienlong Bank | C8: 5040 | D8: Credit debt | F8: 46006 | G8: Khang support | H8: 2000
A9: 45989 | B9: Taxi | C9: 1266 | D9: Travel | F9: 46007 | G9: Bảo | H9: 1000
B10: Đổ xăng | C10: 40 | D10: Living expense | F10: 46010 | G10: Bảo | H10: 1000
B11: Cơm | C11: 100 | D11: Living expense | F11: 23-24-28/12/2025 | G11: Bảo | H11: =1000+200 -> 1200
B12: Đồ chiên | C12: 20 | D12: Living expense
B13: Cà phê | C13: 32 | D13: Living expense | F13: Total earn | G13: =SUM(H2:H12) -> 48119
B14: Sữa ensure | C14: 438 | D14: Credit | F14: Total spent | G14: =SUMIF(D2:D219, "<>Credit", C2:C527) + G15 -> 47857
A15: 45990 | B15: Ăn sáng | C15: 5 | D15: Living expense | F15: Untrack spent | G15: =550+2+45+182+10 -> 789
B16: Help Ly | C16: 500 | D16: Help people | F16: Saving | G16: 0
B17: Taxi | C17: =102+93 -> 195 | D17: Living expense
B18: Bánh canh | C18: 26 | D18: Living expense | F18: Estimate remaining | G18: =G13-G14-J34 -> 262
B19: Cà phê | C19: 32 | D19: Living expense | F19: Remaining without cost | G19: =G13-G14 -> 262
A20: 45991 | B20: Phở | C20: 79 | D20: Living expense
B21: Nước | C21: 27 | D21: Living expense | F21: Category | G21: Estimated | H21: Actual
B22: Taxi | C22: 967 | D22: Travel | F22: Living expense | G22: 5000 | H22: =SUMIF(D2:D142, "=Living expense",C2:C160)+G15 -> 6503
B23: Jolibee | C23: 128 | D23: Living expense
A24: 45992 | B24: Nước ngọt | C24: 14 | D24: Living expense | F24: Planned/actual spend per category of this month
B25: Đưa má tiền đám cưới | C25: 1000 | D25: Other | F25: Category | G25: Estimated | H25: Actual | I25: Finalize | J25: Reserve
B26: Đồ chiên | C26: 50 | D26: Living expense | F26: Gonsa | G26: 3000 | H26: =IFERROR(__xludf.DUMMYFUNCTION("SUMIF($D$2:$D$518, TO_TEXT(F26) ,$C$2:$C$518)"),5000.0) -> 5000 | I26: TRUE | J26: =IF(I26=TRUE,0,MAX(G26-H26,0)) -> 0
B27: Circle K | C27: 49 | D27: Living expense | F27: Rent | G27: 6609 | H27: =IFERROR(__xludf.DUMMYFUNCTION("SUMIF($D$2:$D$518, TO_TEXT(F27) ,$C$2:$C$518)"),6609.0) -> 6609 | I27: TRUE | J27: =IF(I27=TRUE,0,MAX(G27-H27,0)) -> 0
B28: Ăn tối | C28: 65 | D28: Living expense | F28: Help people | G28: 2000 | H28: =IFERROR(__xludf.DUMMYFUNCTION("SUMIF($D$2:$D$518, TO_TEXT(F28) ,$C$2:$C$518)"),1500.0) -> 1500 | I28: TRUE | J28: =IF(I28=TRUE,0,MAX(G28-H28,0)) -> 0
A29: 45993 | B29: Tiền điện | C29: 520 | D29: Rent | F29: Parent | G29: 3000 | H29: =IFERROR(__xludf.DUMMYFUNCTION("SUMIF($D$2:$D$518, TO_TEXT(F29) ,$C$2:$C$518)"),6848.0) -> 6848 | I29: TRUE | J29: =IF(I29=TRUE,0,MAX(G29-H29,0)) -> 0
B30: Cơm | C30: 35 | D30: Living expense | F30: Credit debt | G30: 15250 | H30: =IFERROR(__xludf.DUMMYFUNCTION("SUMIF($D$2:$D$518, TO_TEXT(F30) ,$C$2:$C$518)"),15315.0) -> 15315 | I30: TRUE | J30: =IF(I30=TRUE,0,MAX(G30-H30,0)) -> 0
B31: Sữa | C31: 22 | D31: Living expense | F31: Travel | G31: 2000 | H31: =IFERROR(__xludf.DUMMYFUNCTION("SUMIF($D$2:$D$518, TO_TEXT(F31) ,$C$2:$C$518)"),2233.0) -> 2233 | I31: TRUE | J31: =IF(I31=TRUE,0,MAX(G31-H31,0)) -> 0
B32: Trả tiền nước cho Tú | C32: 27 | D32: Living expense | F32: Khang debt | G32: 1275 | H32: =IFERROR(__xludf.DUMMYFUNCTION("SUMIF($D$2:$D$518, TO_TEXT(F32) ,$C$2:$C$518)"),1275.0) -> 1275 | I32: TRUE | J32: =IF(I32=TRUE,0,MAX(G32-H32,0)) -> 0
B33: Ăn tối | C33: 37 | D33: Living expense | F33: Wedding | G33: 500 | H33: =IFERROR(__xludf.DUMMYFUNCTION("SUMIF($D$2:$D$518, TO_TEXT(F33) ,$C$2:$C$518)"),500.0) -> 500 | I33: TRUE | J33: =IF(I33=TRUE,0,MAX(G33-H33,0)) -> 0
A34: 45994 | B34: An trả | C34: -27 | D34: Living expense | F34: Sum | G34: =SUM(G27:G31) -> 28859 | H34: =SUM(H27:H30) -> 30272 | J34: =SUM(J26:J33) -> 0
B35: Ăn trưa | C35: 30 | D35: Living expense
B36: Ăn chiều | C36: 59 | D36: Living expense
A37: 45995 | B37: Nước ngọt | C37: 14 | D37: Living expense
B38: Thuốc cho Má | C38: 105 | D38: Living expense
B39: Circle K | C39: 90 | D39: Living expense
B40: Order gỏi cuốn | C40: =93-30-30 -> 33 | D40: Living expense
...

Sheet T112025
A1: DATE | B1: SPENT FOR | C1: AMOUNT | D1: TYPE | F1: DATE | G1: EARN BY | H1: AMOUNT
A2: 45960 | B2: Trả Khang | C2: 2000 | D2: Khang debt | F2: 45930 | G2: Cuối T10 | H2: ='T102025'!G18 -> 1664
B3: GS25 | C3: 14 | D3: Living expense | G3: Lương T10 | H3: 27279
B4: Kienlong Bank | C4: 15250 | D4: Credit debt | F4: 45941 | G4: Ba | H4: =2000 -> 2000
B5: Ăn chiều | C5: =115-50 -> 65 | D5: Living expense | F5: 45944 | G5: Kienlong Bank | H5: 10000
B6: Help Nhi | C6: 500 | D6: Help people | F6: 45945 | G6: Bảo | H6: 2500
B7: Help Ly | C7: 500 | D7: Help people | F7: 45946 | G7: Kienlong Bank | H7: 5000
B8: Đồ chiên | C8: 50 | D8: Living expense | F8: 45954 | G8: Khang support | H8: 1000
B9: Sữa Ensure Gold | C9: 791 | D9: Parent | G9: Bảo support | H9: 300
A10: 45961 | B10: Ăn trưa | C10: 30 | D10: Living expense
B11: Gởi Má tiền ăn | C11: 200 | D11: Parent
B12: Ăn chiều | C12: 75 | D12: Living expense
B13: Circle K | C13: 60 | D13: Living expense | F13: Total earn | G13: =SUM(H2:H12) -> 49743
B14: Gởi Má tiền ăn | C14: 2000 | D14: Parent | F14: Total spent | G14: =SUMIF(D2:D213, "<>Credit", C2:C521) + G15 -> 49324
B15: Help Nhi TV | C15: 500 | D15: Help people | F15: Untrack spent | G15: =112+50-63+10+96+20+1+12 -> 238
B16: Help Nhi TV | C16: 100 | D16: Support | F16: Saving | G16: 0
A17: 45962 | B17: Khám bệnh cho Má | C17: =120+608 -> 728 | D17: Parent
B18: Gym | C18: 30 | D18: Living expense | F18: Estimate remaining | G18: =G13-G14-J32 -> 419
B19: Circle K | C19: 131 | D19: Living expense | F19: Remaining without cost | G19: =G13-G14 -> 419
A20: 45963 | B20: Nhi trả | C20: -100 | D20: Support
B21: Nhà thờ | C21: 25 | D21: Living expense | F21: Category | G21: Estimated | H21: Actual
B22: Circle K | C22: 28 | D22: Living expense | F22: Living expense | G22: 5000 | H22: =SUMIF(D2:D136, "=Living expense",C2:C154)+G15 -> 5889
B23: GO | C23: 320 | D23: Buy
A24: 45964 | B24: Nước ngọt | C24: 14 | D24: Living expense | F24: Planned/actual spend per category of this month
B25: Ăn chiều | C25: =108-35 -> 73 | D25: Living expense | F25: Category | G25: Estimated | H25: Actual | I25: Finalize | J25: Reserve
B26: Circle K | C26: 42 | D26: Living expense | F26: Gonsa | G26: 3000 | H26: =IFERROR(__xludf.DUMMYFUNCTION("SUMIF($D$2:$D$512, TO_TEXT(F26) ,$C$2:$C$512)"),5000.0) -> 5000 | I26: TRUE | J26: =IF(I26=TRUE,0,MAX(G26-H26,0)) -> 0
B27: Ăn khuya | C27: 107 | D27: Living expense | F27: Rent | G27: 7000 | H27: =IFERROR(__xludf.DUMMYFUNCTION("SUMIF($D$2:$D$512, TO_TEXT(F27) ,$C$2:$C$512)"),7019.0) -> 7019 | I27: TRUE | J27: =IF(I27=TRUE,0,MAX(G27-H27,0)) -> 0
A28: 45965 | B28: Nước ngọt | C28: 14 | D28: Living expense | F28: Help people | G28: 1500 | H28: =IFERROR(__xludf.DUMMYFUNCTION("SUMIF($D$2:$D$512, TO_TEXT(F28) ,$C$2:$C$512)"),1500.0) -> 1500 | I28: TRUE | J28: =IF(I28=TRUE,0,MAX(G28-H28,0)) -> 0
B29: Ăn chiều | C29: 75 | D29: Living expense | F29: Parent | G29: 3000 | H29: =IFERROR(__xludf.DUMMYFUNCTION("SUMIF($D$2:$D$512, TO_TEXT(F29) ,$C$2:$C$512)"),9063.0) -> 9063 | I29: TRUE | J29: =IF(I29=TRUE,0,MAX(G29-H29,0)) -> 0
B30: GS25 | C30: 43 | D30: Living expense | F30: Credit debt | G30: 15250 | H30: =IFERROR(__xludf.DUMMYFUNCTION("SUMIF($D$2:$D$512, TO_TEXT(F30) ,$C$2:$C$512)"),15250.0) -> 15250 | I30: TRUE | J30: =IF(I30=TRUE,0,MAX(G30-H30,0)) -> 0
B31: Tiền điện | C31: 1019 | D31: Rent | F31: Khang debt | G31: 2000 | H31: =IFERROR(__xludf.DUMMYFUNCTION("SUMIF($D$2:$D$512, TO_TEXT(F31) ,$C$2:$C$512)"),2000.0) -> 2000 | I31: TRUE | J31: =IF(I31=TRUE,0,MAX(G31-H31,0)) -> 0
B32: Ăn khuya | C32: 38 | D32: Living expense | F32: Sum | G32: =SUM(G26:G31) -> 31750 | H32: =SUM(H26:H29) -> 22582 | J32: =SUM(J26:J31) -> 0
A33: 45966 | B33: Taxi khám bệnh cho Ba | C33: =58+65 -> 123 | D33: Parent
B34: Nước ngọt | C34: 14 | D34: Living expense
B35: Ăn chiều | C35: 72 | D35: Living expense
A36: 45967 | B36: Sữa | C36: 13 | D36: Living expense
B37: Đổ xăng | C37: 55 | D37: Living expense
B38: Ăn chiều | C38: 100 | D38: Living expense
B39: Thuốc cảm, khẩu trang | C39: 88 | D39: Living expense
B40: Circle K | C40: 50 | D40: Living expense
...

Sheet T102025
A1: DATE | B1: SPENT FOR | C1: AMOUNT | D1: TYPE | F1: DATE | G1: EARN BY | H1: AMOUNT
A2: 45929 | B2: Trả tín dụng KienlongBank | C2: 15000 | D2: Credit debt | F2: 45929 | G2: Cuối T9 | H2: 149
B3: Trả tiền thuê xe tải | C3: 1500 | D3: Buy | G3: Lương T9 | H3: 20000
B4: Help A Bảo | C4: 2000 | D4: Support | F4: 45935 | G4: Khang support | H4: 2000
A5: 45930 | B5: Tiền điện nước Thanh Duy House | C5: 247 | D5: Living expense | F5: 45941 | G5: Credit | H5: 15000
B6: Tiền nước Rocket | C6: 93 | D6: Living expense | F6: 45942 | G6: Bảo | H6: 2000
B7: GS25 | C7: 26 | D7: Living expense | F7: 45945 | G7: Bảo | H7: 1000
B8: Ăn tối | C8: 82 | D8: Living expense | G8: Mượn Ba | H8: 5480
A9: 45931 | B9: GS25 | C9: 26 | D9: Living expense | F9: 45948 | G9: Bảo | H9: 3000
B10: GS25 trưa | C10: 14 | D10: Living expense | F10: 45951 | G10: Bảo | H10: 700
A11: 45932 | B11: GS25 | C11: 14 | D11: Living expense | F11: 45957 | G11: JICA Bonus | H11: 2000
B12: Jolibee | C12: 70 | D12: Living expense
B13: Game | C13: 365 | D13: Credit | F13: Total earn | G13: =SUM(H2:H12) -> 51329
A14: 45933 | B14: Điện Trà Vinh | C14: 279 | D14: Living expense | F14: Total spent | G14: =SUMIF(D2:D208, "<>Credit", C2:C516) + G15 -> 49665
B15: Điện | C15: 487 | D15: Living expense | F15: Untrack spent | G15: =7 -> 7
B16: Nước | C16: 49 | D16: Living expense | F16: Saving | G16: 0
B17: Ăn tối | C17: 97 | D17: Living expense
A18: 45934 | B18: Game GOW | C18: 463 | D18: Credit | F18: Estimate remaining | G18: =G13-G14-J33 -> 1664
A19: 45935 | B19: Tiền kết | C19: 10 | D19: Living expense | F19: Remaining without cost | G19: =G13-G14 -> 1664
B20: Ensure Gold | C20: 790 | D20: Credit
B21: Circle K | C21: 74 | D21: Credit | F21: Category | G21: Estimated | H21: Actual
A22: 45936 | B22: Khám bệnh cho Má | C22: =2077-1837 -> 240 | D22: Living expense | F22: Living expense | G22: 5000 | H22: =SUMIF(D2:D131, "=Living expense",C2:C149)+G15 -> 7272
B23: Circle K | C23: 14 | D23: Living expense
B24: Ăn chiều | C24: 52 | D24: Living expense | F24: Planned/actual spend per category of this month
B25: Trả a Khoa | C25: 35 | D25: Living expense | F25: Category | G25: Estimated | H25: Actual | I25: Finalize | J25: Reserve
B26: Cho Má | C26: 1000 | D26: Parent | F26: Gonsa | G26: 5000 | H26: =SUMIF($D$2:$D$507, "=Gonsa",$C$2:$C$507) -> 5000 | I26: TRUE | J26: =IF(I26=TRUE,0,MAX(G26-H26,0)) -> 0
A27: 45937 | B27: GS25 | C27: 14 | D27: Living expense | F27: Rent | G27: 5800 | H27: =SUMIF($D$2:$D$507, "=Rent",$C$2:$C$507) -> 5800 | I27: TRUE | J27: =IF(I27=TRUE,0,MAX(G27-H27,0)) -> 0
A28: 45938 | B28: GS25 | C28: 14 | D28: Living expense | F28: Rocket fund | G28: 300 | H28: =SUMIF($D$2:$D$507, "=Rocket fund",$C$2:$C$507) -> 300 | I28: TRUE | J28: =IF(I28=TRUE,0,MAX(G28-H28,0)) -> 0
B29: Order gỏi cuốn | C29: =164-25-25-57 -> 57 | D29: Living expense | F29: Donate | G29: 5000 | H29: =SUMIF($D$2:$D$507, "=Donate",$C$2:$C$507) -> 5000 | I29: TRUE | J29: =IF(I29=TRUE,0,MAX(G29-H29,0)) -> 0
A30: 45939 | B30: GS25 | C30: 40 | D30: Living expense | F30: Help friend | G30: 1000 | H30: =SUMIF($D$2:$D$507, "=Help friend",$C$2:$C$507) -> 1000 | I30: TRUE | J30: =IF(I30=TRUE,0,MAX(G30-H30,0)) -> 0
B31: Ăn chiều | C31: 68 | D31: Living expense | F31: Parent | G31: 4000 | H31: =SUMIF($D$2:$D$507, "=Parent",$C$2:$C$507) -> 5093 | I31: TRUE | J31: =IF(I31=TRUE,0,MAX(G31-H31,0)) -> 0
A32: 45940 | B32: Đổ xăng | C32: 50 | D32: Living expense | F32: Credit debt T10 | G32: 1700 | H32: =SUMIF($D$2:$D$507, "=Credit debt T10",$C$2:$C$507) -> 1700 | I32: TRUE | J32: =IF(I32=TRUE,0,MAX(G32-H32,0)) -> 0
B33: GS25 | C33: 17 | D33: Living expense | F33: Sum | G33: =SUM(G26:G32) -> 22800 | H33: =SUM(H26:H31) -> 22193 | J33: =SUM(J26:J32) -> 0
B34: Ăn trưa | C34: 35 | D34: Living expense
B35: Circle K | C35: 57 | D35: Living expense
A36: 45941 | B36: Taxi | C36: =60+72 -> 132 | D36: Living expense
B37: Viện phí (khám, xét nghiệm, thuốc) | C37: =210+978 -> 1188 | D37: Living expense
B38: Dịch vụ BV | C38: =39+120 -> 159 | D38: Living expense
B39: Sữa Ensure | C39: 790 | D39: Parent
A40: 45942 | B40: Thay kiếng xe | C40: 182 | D40: Living expense
...

Sheet T92025
A1: DATE | B1: SPENT FOR | C1: AMOUNT | D1: TYPE | F1: DATE | G1: EARN BY | H1: AMOUNT
A2: 45897 | B2: GS25 | C2: 24 | D2: Living expense | F2: 45897 | G2: Cuối tháng 8 | H2: 433
B3: Pizza | C3: 304 | D3: Living expense | G3: Lương tháng 8 | H3: 29112
B4: Shopee Pay Later | C4: 1021 | D4: Credit debt | F4: 45911 | G4: Khang help | H4: 1500
B5: Kienlong Bank Credit | C5: 1789 | D5: Credit debt | G5: Bảo gởi Gonsa | H5: 2500
B6: Trả Khang | C6: 3000 | D6: Khang debt | G6: Credit | H6: 15000
A7: 45898 | B7: Ăn trưa | C7: 30 | D7: Living expense | F7: 45915 | G7: Bảo gởi Gonsa | H7: 3000
B8: Nước | C8: 25 | D8: Living expense | G8: Khang help | H8: 2000
